"""
Tests for error handling utilities.

This module contains tests for the error handling utilities.
Following TDD principles, these tests are written before implementing the actual code.

SRP-1: Tests error handling utilities
"""
import unittest
from unittest.mock import patch, MagicMock
from typing import Any

# Import the module to be tested (will be implemented after tests)
# from src.core.utils.error_handling import ErrorHandlingMixin, ApplicationError, OperationError, ValidationError, StorageError


class TestApplicationError(unittest.TestCase):
    """Tests for the ApplicationError class."""

    def test_init(self):
        """Test that ApplicationError initializes correctly."""
        # This test will pass once we implement the ApplicationError
        # with the expected behavior
        try:
            from src.core.utils.error_handling import ApplicationError
            
            # Create an error without a cause
            error = ApplicationError("Test message")
            
            self.assertEqual(str(error), "Test message")
            self.assertIsNone(error.cause)
            self.assertIsNone(error.traceback)
            
            # Create an error with a cause
            cause = ValueError("Cause message")
            error = ApplicationError("Test message", cause)
            
            self.assertEqual(str(error), "Test message")
            self.assertEqual(error.cause, cause)
            self.assertIsNotNone(error.traceback)
        except ImportError:
            self.skipTest("ApplicationError not implemented yet")


class TestErrorTypes(unittest.TestCase):
    """Tests for the specific error types."""

    def test_operation_error(self):
        """Test that OperationError is a subclass of ApplicationError."""
        # This test will pass once we implement the OperationError
        # with the expected behavior
        try:
            from src.core.utils.error_handling import ApplicationError, OperationError
            
            self.assertTrue(issubclass(OperationError, ApplicationError))
            
            # Create an error
            error = OperationError("Test message")
            
            self.assertEqual(str(error), "Test message")
            self.assertIsNone(error.cause)
        except ImportError:
            self.skipTest("OperationError not implemented yet")
            
    def test_validation_error(self):
        """Test that ValidationError is a subclass of ApplicationError."""
        # This test will pass once we implement the ValidationError
        # with the expected behavior
        try:
            from src.core.utils.error_handling import ApplicationError, ValidationError
            
            self.assertTrue(issubclass(ValidationError, ApplicationError))
            
            # Create an error
            error = ValidationError("Test message")
            
            self.assertEqual(str(error), "Test message")
            self.assertIsNone(error.cause)
        except ImportError:
            self.skipTest("ValidationError not implemented yet")
            
    def test_storage_error(self):
        """Test that StorageError is a subclass of ApplicationError."""
        # This test will pass once we implement the StorageError
        # with the expected behavior
        try:
            from src.core.utils.error_handling import ApplicationError, StorageError
            
            self.assertTrue(issubclass(StorageError, ApplicationError))
            
            # Create an error
            error = StorageError("Test message")
            
            self.assertEqual(str(error), "Test message")
            self.assertIsNone(error.cause)
        except ImportError:
            self.skipTest("StorageError not implemented yet")


class TestErrorHandlingMixin(unittest.TestCase):
    """Tests for the ErrorHandlingMixin class."""

    def test_handle_operation(self):
        """Test that handle_operation handles operations correctly."""
        # This test will pass once we implement the ErrorHandlingMixin
        # with the expected behavior
        try:
            from src.core.utils.error_handling import ErrorHandlingMixin, OperationError
            
            class TestClass(ErrorHandlingMixin):
                pass
                
            test_obj = TestClass()
            
            # Mock the log_error method
            test_obj.log_error = MagicMock()
            
            # Define a test operation
            def test_operation(arg1, arg2, kwarg1=None, kwarg2=None):
                return f"{arg1}-{arg2}-{kwarg1}-{kwarg2}"
                
            # Call handle_operation with a successful operation
            result = test_obj.handle_operation(
                "test_operation",
                test_operation,
                "arg1",
                "arg2",
                kwarg1="kwarg1",
                kwarg2="kwarg2"
            )
            
            # Verify the result
            self.assertEqual(result, "arg1-arg2-kwarg1-kwarg2")
            
            # Verify that log_error was not called
            test_obj.log_error.assert_not_called()
            
            # Define a failing operation
            def failing_operation():
                raise ValueError("Test error")
                
            # Call handle_operation with a failing operation
            with self.assertRaises(OperationError) as context:
                test_obj.handle_operation("failing_operation", failing_operation)
                
            # Verify the error
            self.assertEqual(str(context.exception), "Error during failing_operation: Test error")
            self.assertIsInstance(context.exception.cause, ValueError)
            
            # Verify that log_error was called
            test_obj.log_error.assert_called_once()
        except ImportError:
            self.skipTest("ErrorHandlingMixin not implemented yet")
            
    def test_handle_validation(self):
        """Test that handle_validation handles validations correctly."""
        # This test will pass once we implement the ErrorHandlingMixin
        # with the expected behavior
        try:
            from src.core.utils.error_handling import ErrorHandlingMixin, ValidationError
            
            class TestClass(ErrorHandlingMixin):
                pass
                
            test_obj = TestClass()
            
            # Mock the log_error method
            test_obj.log_error = MagicMock()
            
            # Define a test validation
            def test_validation(arg1, arg2, kwarg1=None, kwarg2=None):
                return arg1 == arg2
                
            # Call handle_validation with a successful validation
            result = test_obj.handle_validation(
                "test_validation",
                test_validation,
                "arg1",
                "arg1",
                kwarg1="kwarg1",
                kwarg2="kwarg2"
            )
            
            # Verify the result
            self.assertTrue(result)
            
            # Verify that log_error was not called
            test_obj.log_error.assert_not_called()
            
            # Call handle_validation with a failing validation
            result = test_obj.handle_validation(
                "test_validation",
                test_validation,
                "arg1",
                "arg2",
                kwarg1="kwarg1",
                kwarg2="kwarg2"
            )
            
            # Verify the result
            self.assertFalse(result)
            
            # Verify that log_error was not called
            test_obj.log_error.assert_not_called()
            
            # Define a validation that raises an exception
            def failing_validation():
                raise ValueError("Test error")
                
            # Call handle_validation with a validation that raises an exception
            with self.assertRaises(ValidationError) as context:
                test_obj.handle_validation("failing_validation", failing_validation)
                
            # Verify the error
            self.assertEqual(str(context.exception), "Error during validation failing_validation: Test error")
            self.assertIsInstance(context.exception.cause, ValueError)
            
            # Verify that log_error was called
            test_obj.log_error.assert_called_once()
        except ImportError:
            self.skipTest("ErrorHandlingMixin not implemented yet")
            
    def test_handle_storage(self):
        """Test that handle_storage handles storage operations correctly."""
        # This test will pass once we implement the ErrorHandlingMixin
        # with the expected behavior
        try:
            from src.core.utils.error_handling import ErrorHandlingMixin, StorageError
            
            class TestClass(ErrorHandlingMixin):
                pass
                
            test_obj = TestClass()
            
            # Mock the log_error method
            test_obj.log_error = MagicMock()
            
            # Define a test storage operation
            def test_storage_operation(arg1, arg2, kwarg1=None, kwarg2=None):
                return f"{arg1}-{arg2}-{kwarg1}-{kwarg2}"
                
            # Call handle_storage with a successful storage operation
            result = test_obj.handle_storage(
                "test_storage_operation",
                test_storage_operation,
                "arg1",
                "arg2",
                kwarg1="kwarg1",
                kwarg2="kwarg2"
            )
            
            # Verify the result
            self.assertEqual(result, "arg1-arg2-kwarg1-kwarg2")
            
            # Verify that log_error was not called
            test_obj.log_error.assert_not_called()
            
            # Define a failing storage operation
            def failing_storage_operation():
                raise ValueError("Test error")
                
            # Call handle_storage with a failing storage operation
            with self.assertRaises(StorageError) as context:
                test_obj.handle_storage("failing_storage_operation", failing_storage_operation)
                
            # Verify the error
            self.assertEqual(str(context.exception), "Error during storage operation failing_storage_operation: Test error")
            self.assertIsInstance(context.exception.cause, ValueError)
            
            # Verify that log_error was called
            test_obj.log_error.assert_called_once()
        except ImportError:
            self.skipTest("ErrorHandlingMixin not implemented yet")


if __name__ == "__main__":
    unittest.main()
